<mujoco model="TOE_dog3">
  <compiler angle="radian" meshdir="/home/ubuntu/isaac/t_s/quadruped_rl_blind_walk/legged_gym/resources/robots/TOE_dog3/meshes/"/>

  <asset>
    <mesh name="base_2" file="base_2.STL"/>
    <mesh name="FL_hip" file="FL_hip.STL"/>
    <mesh name="FL_thigh" file="FL_thigh.STL"/>
    <mesh name="calf" file="calf.STL"/>
    <mesh name="TOE_foot" file="TOE_foot.STL"/>
    <mesh name="FR_hip" file="FR_hip.STL"/>
    <mesh name="FR_thigh" file="FR_thigh.STL"/>
    <mesh name="RL_hip" file="RL_hip.STL"/>
    <mesh name="RL_thigh" file="RL_thigh.STL"/>
    <mesh name="RR_hip" file="RR_hip.STL"/>
    <mesh name="RR_thigh" file="RR_thigh.STL"/>
  </asset>

  <worldbody>
    <geom type="mesh" contype="0" conaffinity="0" group="1" density="0" rgba="1 1 1 1" mesh="base_2"/>
    <geom size="0.135 0.063 0.05" type="box" rgba="1 1 1 1"/>
    <body name="FL_hip" pos="0.138 0.063 0">
      <inertial pos="0.0544564 -0.012223 -3.33186e-05" quat="0.0110337 0.707021 -0.0110337 0.707021" mass="5.716" diaginertia="0.067 0.0560312 0.0239688"/>
      <joint name="FL_hip_joint" pos="0 0 0" axis="1 0 0" range="-1 1" actuatorfrcrange="-20 20"/>
      <geom type="mesh" contype="0" conaffinity="0" group="1" density="0" rgba="1 1 1 1" mesh="FL_hip"/>
      <geom size="0.046 0.04" pos="0.064 0.04 0" quat="0.707107 0.707107 0 0" type="cylinder" rgba="1 1 1 1"/>
      <body name="FL_thigh" pos="0.064 0.0673 0">
        <inertial pos="-0.00209131 -0.0157512 -0.0357313" quat="0.708157 0.088053 -0.0563058 0.698276" mass="1.00589" diaginertia="0.00478391 0.00446675 0.000796341"/>
        <joint name="FL_thigh_joint" pos="0 0 0" axis="0 1 0" range="-1.5 2.5" actuatorfrcrange="-20 20"/>
        <geom type="mesh" contype="0" conaffinity="0" group="1" density="0" rgba="1 1 1 1" mesh="FL_thigh"/>
        <geom size="0.05 0.01 0.015" pos="-0.015 0 -0.11" quat="0.707107 0 0.707107 0" type="box" rgba="1 1 1 1"/>
        <body name="FL_calf" pos="0 0 -0.2">
          <inertial pos="0.00837262 -2.88098e-05 -0.123831" quat="0.642674 0.00949052 -0.0225232 0.76575" mass="0.283555" diaginertia="0.00176973 0.00175306 4.79811e-05"/>
          <joint name="FL_calf_joint" pos="0 0 0" axis="0 1 0" range="-2.5 -0.8" actuatorfrcrange="-20 20"/>
          <geom type="mesh" contype="0" conaffinity="0" group="1" density="0" rgba="1 1 1 1" mesh="calf"/>
          <geom size="0.01 0.06" pos="0.008 0 -0.06" quat="0.994493 0 -0.104807 0" type="cylinder" rgba="1 1 1 1"/>
          <geom size="0.011 0.0325" pos="0.02 0 -0.148" quat="0.999688 0 0.0249974 0" type="cylinder"/>
          <geom size="0.0155 0.015" pos="0.00801333 0 -0.18745" quat="0.965093 0 0.261909 0" type="cylinder"/>
          <geom pos="0 0 -0.213" quat="1 0 0 0" type="mesh" contype="0" conaffinity="0" group="1" density="0" rgba="1 1 1 1" mesh="TOE_foot"/>
          <geom size="0.022" pos="-0.002 0 -0.213" rgba="1 1 1 1"/>
        </body>
      </body>
    </body>
    <body name="FR_hip" pos="0.138 -0.063 0">
      <inertial pos="0.0544564 0.012223 3.33186e-05" quat="0.493614 0.493614 0.506305 0.506305" mass="0.72926" diaginertia="0.000973279 0.000664 0.000539721"/>
      <joint name="FR_hip_joint" pos="0 0 0" axis="1 0 0" range="-1 1" actuatorfrcrange="-20 20"/>
      <geom type="mesh" contype="0" conaffinity="0" group="1" density="0" rgba="1 1 1 1" mesh="FR_hip"/>
      <geom size="0.046 0.04" pos="0.064 -0.04 0" quat="0.707107 0.707107 0 0" type="cylinder" rgba="1 1 1 1"/>
      <body name="FR_thigh" pos="0.064 -0.0673 0">
        <inertial pos="-0.00179872 0.0157557 -0.0361369" quat="0.705452 -0.0323703 0.061048 0.705381" mass="1.02069" diaginertia="0.00492032 0.00459719 0.000814487"/>
        <joint name="FR_thigh_joint" pos="0 0 0" axis="0 1 0" range="-1.5 2.5" actuatorfrcrange="-20 20"/>
        <geom type="mesh" contype="0" conaffinity="0" group="1" density="0" rgba="1 1 1 1" mesh="FR_thigh"/>
        <geom size="0.05 0.01 0.015" pos="-0.015 0 -0.11" quat="0.707107 0 0.707107 0" type="box" rgba="1 1 1 1"/>
        <body name="FR_calf" pos="0 0 -0.2">
          <inertial pos="0.00837262 -2.88098e-05 -0.123831" quat="0.706919 -0.0052156 -0.00489906 0.707258" mass="0.283555" diaginertia="0.00177148 0.00175356 4.57348e-05"/>
          <joint name="FR_calf_joint" pos="0 0 0" axis="0 1 0" range="-2.5 -0.8" actuatorfrcrange="-20 20"/>
          <geom type="mesh" contype="0" conaffinity="0" group="1" density="0" rgba="1 1 1 1" mesh="calf"/>
          <geom size="0.01 0.06" pos="0.01 0 -0.06" quat="0.995004 0 -0.0998334 0" type="cylinder" rgba="1 1 1 1"/>
          <geom size="0.011 0.0325" pos="0.02 0 -0.148" quat="0.999688 0 0.0249974 0" type="cylinder"/>
          <geom size="0.0155 0.015" pos="0.00801333 0 -0.18745" quat="0.965093 0 0.261909 0" type="cylinder"/>
          <geom pos="0 0 -0.213" quat="1 0 0 0" type="mesh" contype="0" conaffinity="0" group="1" density="0" rgba="1 1 1 1" mesh="TOE_foot"/>
          <geom size="0.022" pos="-0.002 0 -0.213" rgba="1 1 1 1"/>
        </body>
      </body>
    </body>
    <body name="RL_hip" pos="-0.136 0.063 0">
      <inertial pos="-0.0544564 -0.012223 3.33186e-05" quat="0.492745 0.494482 0.505559 0.507051" mass="0.729266" diaginertia="0.000973282 0.000663997 0.000539721"/>
      <joint name="RL_hip_joint" pos="0 0 0" axis="1 0 0" range="-1 1" actuatorfrcrange="-20 20"/>
      <geom type="mesh" contype="0" conaffinity="0" group="1" density="0" rgba="1 1 1 1" mesh="RL_hip"/>
      <geom size="0.046 0.04" pos="-0.064 0.04 0" quat="0.707107 0.707107 0 0" type="cylinder" rgba="1 1 1 1"/>
      <body name="RL_thigh" pos="-0.064 0.0673 0">
        <inertial pos="-0.00209131 -0.0157512 -0.0357313" quat="0.711046 0.0625847 -0.0312494 0.699657" mass="1.00589" diaginertia="0.00478432 0.00446672 0.000795967"/>
        <joint name="RL_thigh_joint" pos="0 0 0" axis="0 1 0" range="-1.5 2.5" actuatorfrcrange="-20 20"/>
        <geom type="mesh" contype="0" conaffinity="0" group="1" density="0" rgba="1 1 1 1" mesh="RL_thigh"/>
        <geom size="0.05 0.01 0.015" pos="-0.015 0 -0.11" quat="0.707107 0 0.707107 0" type="box" rgba="1 1 1 1"/>
        <body name="RL_calf" pos="0 0 -0.2">
          <inertial pos="0.00837262 -2.88098e-05 -0.123831" quat="0.706919 -0.0052156 -0.00489906 0.707258" mass="0.283555" diaginertia="0.00177148 0.00175356 4.57348e-05"/>
          <joint name="RL_calf_joint" pos="0 0 0" axis="0 1 0" range="-2.5 -0.8" actuatorfrcrange="-20 20"/>
          <geom type="mesh" contype="0" conaffinity="0" group="1" density="0" rgba="1 1 1 1" mesh="calf"/>
          <geom size="0.01 0.06" pos="0.01 0 -0.06" quat="0.995004 0 -0.0998334 0" type="cylinder" rgba="1 1 1 1"/>
          <geom size="0.011 0.0325" pos="0.02 0 -0.148" quat="0.999688 0 0.0249974 0" type="cylinder"/>
          <geom size="0.0155 0.015" pos="0.00801333 0 -0.18745" quat="0.965093 0 0.261909 0" type="cylinder"/>
          <geom pos="0 0 -0.213" quat="1 0 0 0" type="mesh" contype="0" conaffinity="0" group="1" density="0" rgba="1 1 1 1" mesh="TOE_foot"/>
          <geom size="0.022" pos="-0.002 0 -0.213" rgba="1 1 1 1"/>
        </body>
      </body>
    </body>
    <body name="RR_hip" pos="-0.136 -0.063 0">
      <inertial pos="-0.0544564 0.012223 -3.33186e-05" quat="0.505559 0.507051 0.492745 0.494482" mass="0.729266" diaginertia="0.000973282 0.000663997 0.000539721"/>
      <joint name="RR_hip_joint" pos="0 0 0" axis="1 0 0" range="-1 1" actuatorfrcrange="-20 20"/>
      <geom type="mesh" contype="0" conaffinity="0" group="1" density="0" rgba="1 1 1 1" mesh="RR_hip"/>
      <geom size="0.046 0.04" pos="-0.064 -0.04 0" quat="0.707107 0.707107 0 0" type="cylinder" rgba="1 1 1 1"/>
      <body name="RR_thigh" pos="-0.064 -0.0673 0">
        <inertial pos="-0.00179872 0.0157557 -0.0361369" quat="0.705378 -0.0324105 0.0610056 0.705457" mass="1.02069" diaginertia="0.00492032 0.00459715 0.000814527"/>
        <joint name="RR_thigh_joint" pos="0 0 0" axis="0 1 0" range="-1.5 2.5" actuatorfrcrange="-20 20"/>
        <geom type="mesh" contype="0" conaffinity="0" group="1" density="0" rgba="1 1 1 1" mesh="RR_thigh"/>
        <geom size="0.05 0.01 0.015" pos="-0.015 0 -0.11" quat="0.707107 0 0.707107 0" type="box" rgba="1 1 1 1"/>
        <body name="RR_calf" pos="0 0 -0.213">
          <inertial pos="0.00837262 -2.88098e-05 -0.123831" quat="0.706919 -0.0052156 -0.00489906 0.707258" mass="0.283555" diaginertia="0.00177148 0.00175356 4.57348e-05"/>
          <joint name="RR_calf_joint" pos="0 0 0" axis="0 1 0" range="-2.5 -0.8" actuatorfrcrange="-20 20"/>
          <geom type="mesh" contype="0" conaffinity="0" group="1" density="0" rgba="1 1 1 1" mesh="calf"/>
          <geom size="0.01 0.06" pos="0.01 0 -0.06" quat="0.995004 0 -0.0998334 0" type="cylinder" rgba="1 1 1 1"/>
          <geom size="0.011 0.0325" pos="0.02 0 -0.148" quat="0.999688 0 0.0249974 0" type="cylinder"/>
          <geom size="0.0155 0.015" pos="0.00801333 0 -0.18745" quat="0.965093 0 0.261909 0" type="cylinder"/>
          <geom pos="0 0 -0.213" quat="1 0 0 0" type="mesh" contype="0" conaffinity="0" group="1" density="0" rgba="1 1 1 1" mesh="TOE_foot"/>
          <geom size="0.022" pos="-0.002 0 -0.213" rgba="1 1 1 1"/>
        </body>
      </body>
    </body>
  </worldbody>
</mujoco>
